<?xml version="1.0"?>
<robot xmlns:xacro="http://www.ros.org/wiki/xacro" >

    <xacro:include filename="inertial_macros.xacro"/>

    <material name="white">
        <color rgba="1 1 1 1" />
    </material>

    <material name="orange">
        <color rgba="1 0.3 0.1 1"/>
    </material>

    <material name="blue">
        <color rgba="0.2 0.2 1 1"/>
    </material>

    <material name="black">
        <color rgba="0 0 0 1"/>
    </material>

    <material name="yellow">
        <color rgba="1.00 0.792 0.0400 1"/>
    </material>

    <material name="grey">
        <color rgba="0.616 0.616 0.616 1"/>
    </material>

    <!-- BASE LINK -->

    <link name="base_link">

    </link>

    <!-- BASE FOOTPRINT LINK-->

    <joint name="base_footprint_joint" type="fixed">
        <parent link="base_link"/>
        <child link="base_footprint"/>
        <origin xyz="0 0 0.1" rpy="0 0 0"/>
    </joint>

    <link name="base_footprint"></link>


    <!-- CHASSIS LINK -->

    <joint name="chassis_joint" type="fixed">
        <parent link="base_footprint"/>
        <child link="chassis"/>
        <origin xyz="-0.1 0 0"/>
    </joint>

    <link name="chassis">
        <visual>
            <origin xyz="0.426 0 0.130"/>
            <geometry>
                <box size="0.810 0.500 0.259"/>
            </geometry>
            <material name="yellow"/>
        </visual>
        <!-- <collision>
            <origin xyz="0.426 0 0.130"/>
            <geometry>
                <box size="0.01 0.01 0.01"/>
                <box size="0.810 0.500 0.259"/>
            </geometry>
        </collision> -->
        <xacro:inertial_box mass="0.3" x="0.810" y="0.500" z="0.259">
            <origin xyz="0.426 0 0.130" rpy="0 0 0"/>
        </xacro:inertial_box>
        <!-- <xacro:inertial_box mass="1" x="0.810" y="0.500" z="0.259">
            <origin xyz="0 0 0" rpy="0 0 0"/>
        </xacro:inertial_box> -->
    </link>

    <gazebo reference="chassis">
        <material>Gazebo/Yellow</material>
    </gazebo>

    <!-- LEFT WHEEL LINK -->

    <joint name="left_wheel_joint" type="continuous">
        <parent link="base_footprint"/>
        <child link="left_wheel"/>
        <origin xyz="0 0.220 0" rpy="-${pi/2} 0 0" />
        <axis xyz="0 0 1"/>
    </joint>

    <link name="left_wheel">
        <visual>
            <geometry>
                <cylinder radius="0.1" length="0.06"/>
            </geometry>
            <material name="black"/>
        </visual>
        <collision>
            <geometry>
                <sphere radius="0.1"/>
            </geometry>
        </collision>
        <xacro:inertial_cylinder mass="0.3" length="0.06" radius="0.1">
            <origin xyz="0 0 0" rpy="0 0 0"/>
        </xacro:inertial_cylinder>
    </link>

    <gazebo reference="left_wheel">
        <material>Gazebo/Black</material>
    </gazebo>

    <!-- RIGHT WHEEL LINK -->

    <joint name="right_wheel_joint" type="continuous">
        <parent link="base_footprint"/>
        <child link="right_wheel"/>
        <origin xyz="0 -0.220 0" rpy="${pi/2} 0 0" />
        <axis xyz="0 0 -1"/>
    </joint>

    <link name="right_wheel">
        <visual>
            <geometry>
                <cylinder radius="0.1" length="0.06"/>
            </geometry>
            <material name="black"/>
        </visual>
        <collision>
            <geometry>
                <sphere radius="0.1"/>
            </geometry>
        </collision>
        <xacro:inertial_cylinder mass="0.3" length="0.06" radius="0.1">
            <origin xyz="0 0 0" rpy="0 0 0"/>
        </xacro:inertial_cylinder>
    </link>

    <gazebo reference="right_wheel">
        <material>Gazebo/Black</material>
    </gazebo>

    <!-- CASTER WHEEL LINK -->

    <joint name="caster_wheel_joint" type="fixed">
        <parent link="chassis"/>
        <child link="caster_wheel"/>
        <origin xyz="0.970 0 0"/>
    </joint>


    <link name="caster_wheel">
        <visual>
            <geometry>
                <sphere radius="0.0675"/>
            </geometry>
            <material name="white"/>
        </visual>
        <collision>
            <geometry>
                <sphere radius="0.0675"/>
            </geometry>
        </collision>
        <xacro:inertial_sphere mass="0.3" radius="0.0675">
            <origin xyz="0 0 0"/>
        </xacro:inertial_sphere>
    </link>

    <gazebo reference="caster_wheel">
        <material>Gazebo/White</material>
        <mu1 value="0.001"/>
        <mu2 value="0.001"/>
    </gazebo>
    
    
</robot>